Workbook
Name WEEKS: Inputs!$B$4
Name TOTAL_BED_CAP: Inputs!$B$5
Name FIXED_COSTS_OTHER: Inputs!$B$8
Name FARMER_SALARY: Inputs!$B$11
Name FARMER_TOTAL_HOURS: Inputs!$B$12
Name FARMER_FIELD_SHARE: Inputs!$B$13
Name FARMER_FIELD_HOURS: Inputs!$B$14
Name FARMER_RATE: Inputs!$B$15
Name TEMP_WORKER_COST: Inputs!$B$18
Name TEMP_WORKER_HOURS: Inputs!$B$19
Name TEMP_RATE: Inputs!$B$20
Name MAX_TEMP_WORKERS: Inputs!$B$21
Name TOM_BED_CAP: Inputs!$B$25
Name TOM_PRICE: Inputs!$C$25
Name TOM_HRS_PER_BED: Inputs!$D$25
Name TOM_FERT_COST: Inputs!$E$25
Name TOM_DIM_PCT: Inputs!$F$25
Name CAR_BED_CAP: Inputs!$B$26
Name CAR_PRICE: Inputs!$C$26
Name CAR_HRS_PER_BED: Inputs!$D$26
Name CAR_FERT_COST: Inputs!$E$26
Name CAR_DIM_PCT: Inputs!$F$26
Name MES_BED_CAP: Inputs!$B$27
Name MES_PRICE: Inputs!$C$27
Name MES_HRS_PER_BED: Inputs!$D$27
Name MES_FERT_COST: Inputs!$E$27
Name MES_DIM_PCT: Inputs!$F$27

Sheet Inputs
A1: Perfect Competition Farm — Model Inputs
A3: Season & Farm
A4: Season length (weeks) | B4: 36
A5: Total beds available (16 beds x 4 plots) | B5: 64
A6: Beds per plot | B6: 16
A7: Number of plots | B7: 4
A8: Fixed costs ($/season) | B8: 20000
A10: Farmer Labor
A11: Farmer salary ($/season) | B11: 50000
A12: Farmer total season hours (implied) | B12: 1440
A13: Farmer share of time in field | B13: 0.5
A14: Farmer field hours (season) | B14: =FARMER_TOTAL_HOURS*FARMER_FIELD_SHARE
A15: Farmer implied hourly rate ($/hr) | B15: =FARMER_SALARY/FARMER_TOTAL_HOURS
A17: Temporary Workers
A18: Cost per temp worker ($/season) | B18: 25000
A19: Hours per temp worker (season) | B19: 1440
A20: Temp worker implied hourly rate ($/hr) | B20: =TEMP_WORKER_COST/TEMP_WORKER_HOURS
A21: Max temp workers allowed | B21: 4
A23: Crop Economics
A24: Crop | B24: Max beds | C24: Price $/bed | D24: Labor hrs/wk/bed | E24: Fertilizer $/bed | F24: Diminishing returns %/bed
A25: Tomatoes | B25: 20 | C25: 8800 | D25: 2.5 | E25: 880 | F25: 0.1
A26: Carrots | B26: 20 | C26: 2094 | D26: =5/6 | E26: 440 | F26: 0.025
A27: Mesclun | B27: 30 | C27: 2700 | D27: 1.25 | E27: 880 | F27: 0.0125
A29: All figures above are given in the case data (blue = hardcoded input). Farmer field hours and hourly rates are derived by formula from the salary/hours/share inputs. Carrots' labor hrs/wk/bed is stored as the exact fraction 5/6, not the rounded 0.833 a display might show — the rounding difference alone is worth about $7 of profit at the published optimum.

Sheet Solver Model
A1: Solver Model — Decision Variables & Settings
A3: Decision Cells (Solver's Changing Variable Cells)
A4: Beds — Tomatoes | B4: 10
A5: Beds — Carrots | B5: 20
A6: Beds — Mesclun | B6: 30
A7: Total beds used | B7: =B4+B5+B6
A8: Temp labor hours required (raw, linked from P&L) | B8: ='P&L'!B12
A10: Constraint Check
A11: Tomatoes beds <= max (20) | B11: =IF(B4<=TOM_BED_CAP,"OK","EXCEEDS")
A12: Carrots beds <= max (20) | B12: =IF(B5<=CAR_BED_CAP,"OK","EXCEEDS")
A13: Mesclun beds <= max (30) | B13: =IF(B6<=MES_BED_CAP,"OK","EXCEEDS")
A14: Total beds <= cap (64) | B14: =IF(B7<=TOTAL_BED_CAP,"OK","EXCEEDS")
A15: Temp labor hours <= available (4 workers x 1,440 hrs) | B15: =IF(B8<=MAX_TEMP_WORKERS*TEMP_WORKER_HOURS,"OK","EXCEEDS")
A16: Beds are non-negative integers — enforced in Solver via an "int" constraint on B4:B6 (see setup below).
A18: Objective
A19: Profit (maximize) — linked from P&L Convention A | B19: ='P&L'!B22
A21: Solver Setup (Data > Analysis > Solver)
A22: Set Objective: 'Solver Model'!$B$19 (Profit, Convention A) -> To: Max
A23: By Changing Variable Cells: 'Solver Model'!$B$4:$B$6 (Beds - Tomatoes, Carrots, Mesclun)
A24: Subject to the Constraints:
A25: $B$4 <= Inputs!$B$25 (Tomatoes <= 20 beds)
A26: $B$5 <= Inputs!$B$26 (Carrots <= 20 beds)
A27: $B$6 <= Inputs!$B$27 (Mesclun <= 30 beds)
A28: $B$7 <= Inputs!$B$5 (Total beds <= 64)
A29: $B$8 <= MAX_TEMP_WORKERS*TEMP_WORKER_HOURS (Temp labor hours <= 5,760)
A30: $B$4:$B$6 = integer
A31: $B$4:$B$6 >= 0
A32: Solving Method: GRG Nonlinear
... A36: Run Log — Path-Dependence Check
A37: Run | B37: Start T | C37: Start C | D37: Start M | E37: Final T | F37: Final C | G37: Final M | H37: Final Profit | I37: Notes
A38: Run 1 | B38: 0 | C38: 0 | D38: 0
A39: Run 2 | B39: 20 | C39: 0 | D39: 0
A41: Path-dependence conclusion | B41: =IF(OR(H38="",H39=""),"Pending — run Solver from both starting points above and paste the Final results (E:H) for Run 1 and Run 2.",IF(ROUND(H38,2)=ROUND(H39,2),"Same optimum reached from both starts — no path-dependence detected in this instance.","Path-dependent: the two starts converge to different local optima (Run 1 profit "&TEXT(H38,"$#,##0")&" vs Run 2 profit "&TEXT(H39,"$#,##0")&"). Report the higher-profit run; the (1+dim%)^q term makes the objective non-convex, so GRG Nonlinear is only guaranteed to find a local optimum."))
A43: Independent reference (not a Solver output)
A44: Published answer for this case (hours consumed, priced continuously at FARMER_RATE and TEMP_RATE): Tomatoes=10, Carrots=20, Mesclun=30 (60 beds, profit $42,761.66) — this is the acceptance target for Check 6 in the Audit sheet. A discrete whole-worker-block costing convention instead gives Tomatoes=10, Carrots=19, Mesclun=28 (57 beds, profit $16,586); that is a defensible alternative reading, argued in the Stage 1.3 memo, but is not what this workbook's P&L computes.

Sheet Engine
A1: Engine — Labor Hours Formula (the one formula that drives the model)
A3: Labor hours for q beds = q x hrs-per-week-per-bed x 36 weeks x (1 + diminishing%)^q
A5: Crop | B5: Beds used (q) | C5: Labor hrs/wk/bed | D5: Season weeks | E5: Diminishing %/bed | F5: Labor Hours Required
A6: Tomatoes | B6: ='Solver Model'!B4 | C6: =TOM_HRS_PER_BED | D6: =WEEKS | E6: =TOM_DIM_PCT | F6: =B6*C6*D6*(1+E6)^B6
A7: Carrots | B7: ='Solver Model'!B5 | C7: =CAR_HRS_PER_BED | D7: =WEEKS | E7: =CAR_DIM_PCT | F7: =B7*C7*D7*(1+E7)^B7
A8: Mesclun | B8: ='Solver Model'!B6 | C8: =MES_HRS_PER_BED | D8: =WEEKS | E8: =MES_DIM_PCT | F8: =B8*C8*D8*(1+E8)^B8
A9: Total | F9: =SUM(F6:F8)
A11: Marginal Cost Explorer — this is the true per-bed marginal cost under Convention A (continuous hourly costing), audit check 2 (matches Farm Profit Lab convention)
A12: Crop tested | B12: Tomatoes
A13: Bed count tested (q) — must be >= 1 | B13: 10
A14: Labor hrs/wk/bed | B14: =TOM_HRS_PER_BED
A15: Diminishing %/bed | B15: =TOM_DIM_PCT
A16: Labor hours at q | B16: =B13*B14*WEEKS*(1+B15)^B13
A17: Labor hours at q-1 | B17: =(B13-1)*B14*WEEKS*(1+B15)^(B13-1)
A18: Marginal labor hours (delta for the q-th bed) | B18: =B16-B17
A19: Free hours remaining before this bed (farmer, isolated view) | B19: =MAX(FARMER_FIELD_HOURS-B17,0)
A20: Free hours used by this bed | B20: =MIN(B18,B19)
A21: Paid (temp-rate) hours for this bed | B21: =B18-B20
A22: Marginal labor $ (free hours x farmer rate + paid hours x temp rate) | B22: =B20*FARMER_RATE+B21*(TEMP_WORKER_COST/TEMP_WORKER_HOURS)
A23: Marginal fertilizer $ (constant per bed) | B23: =TOM_FERT_COST
A24: Marginal cost of the q-th bed (labor + fertilizer) | B24: =B22+B23
A25: Marginal revenue (price per bed) | B25: =TOM_PRICE
A26: Marginal profit of the q-th bed | B26: =B25-B24
A28: Farm Profit Lab reference value (paste here)
A29: Match? | B29: =IF(B28="","Pending — paste Farm Profit Lab figure",IF(ROUND(B28,2)=ROUND(B24,2),"MATCH","REVIEW — differs from Farm Profit Lab"))

Sheet Marginal Analysis
A1: Marginal Analysis — Where Marginal Cost Crosses Price
A3: Convention: each crop is evaluated on its own labor-hours curve as if it alone drew on the farmer's 720 free field hours before any paid labor begins. Every hour is priced continuously: the farmer's own hours at her implied rate (FARMER_RATE = $34.72/hr) and hours beyond that at the temp-worker rate (TEMP_RATE = $17.36/hr). This decomposes the farm-wide P&L's aggregate labor cost bed by bed — summed across all beds, it reproduces the same total the P&L computes, which pricing free hours at $0 would not.
A7: Tomatoes (price = Inputs!C25)
A8: q | B8: Cum. hours thru q-1 | C8: Cum. hours thru q | D8: Marginal hours | E8: Free hours (farmer) | F8: Paid hours (temp) | G8: Marginal labor $ | H8: Marginal fertilizer $ | I8: Marginal cost | J8: Price | K8: Marginal profit | L8: Profitable?
A9: 1 | B9: =IF(1-1<=0,0,(1-1)*TOM_HRS_PER_BED*WEEKS*(1+TOM_DIM_PCT)^(1-1)) | C9: =1*TOM_HRS_PER_BED*WEEKS*(1+TOM_DIM_PCT)^1 | D9: =C9-B9 | E9: =MIN(D9,MAX(FARMER_FIELD_HOURS-B9,0)) | F9: =D9-E9 | G9: =E9*FARMER_RATE+F9*(TEMP_WORKER_COST/TEMP_WORKER_HOURS) | H9: =TOM_FERT_COST | I9: =G9+H9 | J9: =TOM_PRICE | K9: =J9-I9 | L9: =IF(K9>=0,"Yes","No")
A10: 2 | B10: =IF(2-1<=0,0,(2-1)*TOM_HRS_PER_BED*WEEKS*(1+TOM_DIM_PCT)^(2-1)) | C10: =2*TOM_HRS_PER_BED*WEEKS*(1+TOM_DIM_PCT)^2 | D10: =C10-B10 | E10: =MIN(D10,MAX(FARMER_FIELD_HOURS-B10,0)) | F10: =D10-E10 | G10: =E10*FARMER_RATE+F10*(TEMP_WORKER_COST/TEMP_WORKER_HOURS) | H10: =TOM_FERT_COST | I10: =G10+H10 | J10: =TOM_PRICE | K10: =J10-I10 | L10: =IF(K10>=0,"Yes","No")
A11: 3 | B11: =IF(3-1<=0,0,(3-1)*TOM_HRS_PER_BED*WEEKS*(1+TOM_DIM_PCT)^(3-1)) | C11: =3*TOM_HRS_PER_BED*WEEKS*(1+TOM_DIM_PCT)^3 | D11: =C11-B11 | E11: =MIN(D11,MAX(FARMER_FIELD_HOURS-B11,0)) | F11: =D11-E11 | G11: =E11*FARMER_RATE+F11*(TEMP_WORKER_COST/TEMP_WORKER_HOURS) | H11: =TOM_FERT_COST | I11: =G11+H11 | J11: =TOM_PRICE | K11: =J11-I11 | L11: =IF(K11>=0,"Yes","No")
A12: 4 | B12: =IF(4-1<=0,0,(4-1)*TOM_HRS_PER_BED*WEEKS*(1+TOM_DIM_PCT)^(4-1)) | C12: =4*TOM_HRS_PER_BED*WEEKS*(1+TOM_DIM_PCT)^4 | D12: =C12-B12 | E12: =MIN(D12,MAX(FARMER_FIELD_HOURS-B12,0)) | F12: =D12-E12 | G12: =E12*FARMER_RATE+F12*(TEMP_WORKER_COST/TEMP_WORKER_HOURS) | H12: =TOM_FERT_COST | I12: =G12+H12 | J12: =TOM_PRICE | K12: =J12-I12 | L12: =IF(K12>=0,"Yes","No")
A13: 5 | B13: =IF(5-1<=0,0,(5-1)*TOM_HRS_PER_BED*WEEKS*(1+TOM_DIM_PCT)^(5-1)) | C13: =5*TOM_HRS_PER_BED*WEEKS*(1+TOM_DIM_PCT)^5 | D13: =C13-B13 | E13: =MIN(D13,MAX(FARMER_FIELD_HOURS-B13,0)) | F13: =D13-E13 | G13: =E13*FARMER_RATE+F13*(TEMP_WORKER_COST/TEMP_WORKER_HOURS) | H13: =TOM_FERT_COST | I13: =G13+H13 | J13: =TOM_PRICE | K13: =J13-I13 | L13: =IF(K13>=0,"Yes","No")
A14: 6 | B14: =IF(6-1<=0,0,(6-1)*TOM_HRS_PER_BED*WEEKS*(1+TOM_DIM_PCT)^(6-1)) | C14: =6*TOM_HRS_PER_BED*WEEKS*(1+TOM_DIM_PCT)^6 | D14: =C14-B14 | E14: =MIN(D14,MAX(FARMER_FIELD_HOURS-B14,0)) | F14: =D14-E14 | G14: =E14*FARMER_RATE+F14*(TEMP_WORKER_COST/TEMP_WORKER_HOURS) | H14: =TOM_FERT_COST | I14: =G14+H14 | J14: =TOM_PRICE | K14: =J14-I14 | L14: =IF(K14>=0,"Yes","No")
A15: 7 | B15: =IF(7-1<=0,0,(7-1)*TOM_HRS_PER_BED*WEEKS*(1+TOM_DIM_PCT)^(7-1)) | C15: =7*TOM_HRS_PER_BED*WEEKS*(1+TOM_DIM_PCT)^7 | D15: =C15-B15 | E15: =MIN(D15,MAX(FARMER_FIELD_HOURS-B15,0)) | F15: =D15-E15 | G15: =E15*FARMER_RATE+F15*(TEMP_WORKER_COST/TEMP_WORKER_HOURS) | H15: =TOM_FERT_COST | I15: =G15+H15 | J15: =TOM_PRICE | K15: =J15-I15 | L15: =IF(K15>=0,"Yes","No")
A16: 8 | B16: =IF(8-1<=0,0,(8-1)*TOM_HRS_PER_BED*WEEKS*(1+TOM_DIM_PCT)^(8-1)) | C16: =8*TOM_HRS_PER_BED*WEEKS*(1+TOM_DIM_PCT)^8 | D16: =C16-B16 | E16: =MIN(D16,MAX(FARMER_FIELD_HOURS-B16,0)) | F16: =D16-E16 | G16: =E16*FARMER_RATE+F16*(TEMP_WORKER_COST/TEMP_WORKER_HOURS) | H16: =TOM_FERT_COST | I16: =G16+H16 | J16: =TOM_PRICE | K16: =J16-I16 | L16: =IF(K16>=0,"Yes","No")
A17: 9 | B17: =IF(9-1<=0,0,(9-1)*TOM_HRS_PER_BED*WEEKS*(1+TOM_DIM_PCT)^(9-1)) | C17: =9*TOM_HRS_PER_BED*WEEKS*(1+TOM_DIM_PCT)^9 | D17: =C17-B17 | E17: =MIN(D17,MAX(FARMER_FIELD_HOURS-B17,0)) | F17: =D17-E17 | G17: =E17*FARMER_RATE+F17*(TEMP_WORKER_COST/TEMP_WORKER_HOURS) | H17: =TOM_FERT_COST | I17: =G17+H17 | J17: =TOM_PRICE | K17: =J17-I17 | L17: =IF(K17>=0,"Yes","No")
A18: 10 | B18: =IF(10-1<=0,0,(10-1)*TOM_HRS_PER_BED*WEEKS*(1+TOM_DIM_PCT)^(10-1)) | C18: =10*TOM_HRS_PER_BED*WEEKS*(1+TOM_DIM_PCT)^10 | D18: =C18-B18 | E18: =MIN(D18,MAX(FARMER_FIELD_HOURS-B18,0)) | F18: =D18-E18 | G18: =E18*FARMER_RATE+F18*(TEMP_WORKER_COST/TEMP_WORKER_HOURS) | H18: =TOM_FERT_COST | I18: =G18+H18 | J18: =TOM_PRICE | K18: =J18-I18 | L18: =IF(K18>=0,"Yes","No")
A19: 11 | B19: =IF(11-1<=0,0,(11-1)*TOM_HRS_PER_BED*WEEKS*(1+TOM_DIM_PCT)^(11-1)) | C19: =11*TOM_HRS_PER_BED*WEEKS*(1+TOM_DIM_PCT)^11 | D19: =C19-B19 | E19: =MIN(D19,MAX(FARMER_FIELD_HOURS-B19,0)) | F19: =D19-E19 | G19: =E19*FARMER_RATE+F19*(TEMP_WORKER_COST/TEMP_WORKER_HOURS) | H19: =TOM_FERT_COST | I19: =G19+H19 | J19: =TOM_PRICE | K19: =J19-I19 | L19: =IF(K19>=0,"Yes","No")
A20: 12 | B20: =IF(12-1<=0,0,(12-1)*TOM_HRS_PER_BED*WEEKS*(1+TOM_DIM_PCT)^(12-1)) | C20: =12*TOM_HRS_PER_BED*WEEKS*(1+TOM_DIM_PCT)^12 | D20: =C20-B20 | E20: =MIN(D20,MAX(FARMER_FIELD_HOURS-B20,0)) | F20: =D20-E20 | G20: =E20*FARMER_RATE+F20*(TEMP_WORKER_COST/TEMP_WORKER_HOURS) | H20: =TOM_FERT_COST | I20: =G20+H20 | J20: =TOM_PRICE | K20: =J20-I20 | L20: =IF(K20>=0,"Yes","No")
A22: Beds 1-4 draw only on the farmer's already-paid-for hours, so marginal cost sits near the $880 fertilizer floor. The farmer's 720 hours run out partway through bed 5, so bed 6 is the first bed priced entirely at the $17.36/hr temp rate -- marginal cost jumps sharply there rather than climbing smoothly from bed 1. Marginal cost stays below the $8,800 price through bed 10 ($8,249) and crosses above it at bed 11 ($9,391) -- tomatoes are self-limiting at 10 beds on economics alone, regardless of the bed cap.
A26: Carrots (price = Inputs!C26) -- approaching the 20-bed cap
A27: q | B27: Cum. hours thru q-1 | C27: Cum. hours thru q | D27: Marginal hours | E27: Free hours (farmer) | F27: Paid hours (temp) | G27: Marginal labor $ | H27: Marginal fertilizer $ | I27: Marginal cost | J27: Price | K27: Marginal profit | L27: Profitable?
A28: 16 | B28: =IF(16-1<=0,0,(16-1)*CAR_HRS_PER_BED*WEEKS*(1+CAR_DIM_PCT)^(16-1)) | C28: =16*CAR_HRS_PER_BED*WEEKS*(1+CAR_DIM_PCT)^16 | D28: =C28-B28 | E28: =MIN(D28,MAX(FARMER_FIELD_HOURS-B28,0)) | F28: =D28-E28 | G28: =E28*FARMER_RATE+F28*(TEMP_WORKER_COST/TEMP_WORKER_HOURS) | H28: =CAR_FERT_COST | I28: =G28+H28 | J28: =CAR_PRICE | K28: =J28-I28 | L28: =IF(K28>=0,"Yes","No")
A29: 17 | B29: =IF(17-1<=0,0,(17-1)*CAR_HRS_PER_BED*WEEKS*(1+CAR_DIM_PCT)^(17-1)) | C29: =17*CAR_HRS_PER_BED*WEEKS*(1+CAR_DIM_PCT)^17 | D29: =C29-B29 | E29: =MIN(D29,MAX(FARMER_FIELD_HOURS-B29,0)) | F29: =D29-E29 | G29: =E29*FARMER_RATE+F29*(TEMP_WORKER_COST/TEMP_WORKER_HOURS) | H29: =CAR_FERT_COST | I29: =G29+H29 | J29: =CAR_PRICE | K29: =J29-I29 | L29: =IF(K29>=0,"Yes","No")
A30: 18 | B30: =IF(18-1<=0,0,(18-1)*CAR_HRS_PER_BED*WEEKS*(1+CAR_DIM_PCT)^(18-1)) | C30: =18*CAR_HRS_PER_BED*WEEKS*(1+CAR_DIM_PCT)^18 | D30: =C30-B30 | E30: =MIN(D30,MAX(FARMER_FIELD_HOURS-B30,0)) | F30: =D30-E30 | G30: =E30*FARMER_RATE+F30*(TEMP_WORKER_COST/TEMP_WORKER_HOURS) | H30: =CAR_FERT_COST | I30: =G30+H30 | J30: =CAR_PRICE | K30: =J30-I30 | L30: =IF(K30>=0,"Yes","No")
A31: 19 | B31: =IF(19-1<=0,0,(19-1)*CAR_HRS_PER_BED*WEEKS*(1+CAR_DIM_PCT)^(19-1)) | C31: =19*CAR_HRS_PER_BED*WEEKS*(1+CAR_DIM_PCT)^19 | D31: =C31-B31 | E31: =MIN(D31,MAX(FARMER_FIELD_HOURS-B31,0)) | F31: =D31-E31 | G31: =E31*FARMER_RATE+F31*(TEMP_WORKER_COST/TEMP_WORKER_HOURS) | H31: =CAR_FERT_COST | I31: =G31+H31 | J31: =CAR_PRICE | K31: =J31-I31 | L31: =IF(K31>=0,"Yes","No")
A32: 20 | B32: =IF(20-1<=0,0,(20-1)*CAR_HRS_PER_BED*WEEKS*(1+CAR_DIM_PCT)^(20-1)) | C32: =20*CAR_HRS_PER_BED*WEEKS*(1+CAR_DIM_PCT)^20 | D32: =C32-B32 | E32: =MIN(D32,MAX(FARMER_FIELD_HOURS-B32,0)) | F32: =D32-E32 | G32: =E32*FARMER_RATE+F32*(TEMP_WORKER_COST/TEMP_WORKER_HOURS) | H32: =CAR_FERT_COST | I32: =G32+H32 | J32: =CAR_PRICE | K32: =J32-I32 | L32: =IF(K32>=0,"Yes","No")
A33: 21 | B33: =IF(21-1<=0,0,(21-1)*CAR_HRS_PER_BED*WEEKS*(1+CAR_DIM_PCT)^(21-1)) | C33: =21*CAR_HRS_PER_BED*WEEKS*(1+CAR_DIM_PCT)^21 | D33: =C33-B33 | E33: =MIN(D33,MAX(FARMER_FIELD_HOURS-B33,0)) | F33: =D33-E33 | G33: =E33*FARMER_RATE+F33*(TEMP_WORKER_COST/TEMP_WORKER_HOURS) | H33: =CAR_FERT_COST | I33: =G33+H33 | J33: =CAR_PRICE | K33: =J33-I33 | L33: =IF(K33>=0,"Yes","No")
A35: Marginal cost is still well below the $2,094 price at bed 20, the last bed the 20-bed cap allows. Bed 21 (blocked by the cap) would still have earned about $353 -- the cap, not the economics, stops production here. That $353 is the shadow value of one more bed of ground.
A38: Mesclun (price = Inputs!C27) -- approaching the 30-bed cap
A39: q | B39: Cum. hours thru q-1 | C39: Cum. hours thru q | D39: Marginal hours | E39: Free hours (farmer) | F39: Paid hours (temp) | G39: Marginal labor $ | H39: Marginal fertilizer $ | I39: Marginal cost | J39: Price | K39: Marginal profit | L39: Profitable?
A40: 26 | B40: =IF(26-1<=0,0,(26-1)*MES_HRS_PER_BED*WEEKS*(1+MES_DIM_PCT)^(26-1)) | C40: =26*MES_HRS_PER_BED*WEEKS*(1+MES_DIM_PCT)^26 | D40: =C40-B40 | E40: =MIN(D40,MAX(FARMER_FIELD_HOURS-B40,0)) | F40: =D40-E40 | G40: =E40*FARMER_RATE+F40*(TEMP_WORKER_COST/TEMP_WORKER_HOURS) | H40: =MES_FERT_COST | I40: =G40+H40 | J40: =MES_PRICE | K40: =J40-I40 | L40: =IF(K40>=0,"Yes","No")
A41: 27 | B41: =IF(27-1<=0,0,(27-1)*MES_HRS_PER_BED*WEEKS*(1+MES_DIM_PCT)^(27-1)) | C41: =27*MES_HRS_PER_BED*WEEKS*(1+MES_DIM_PCT)^27 | D41: =C41-B41 | E41: =MIN(D41,MAX(FARMER_FIELD_HOURS-B41,0)) | F41: =D41-E41 | G41: =E41*FARMER_RATE+F41*(TEMP_WORKER_COST/TEMP_WORKER_HOURS) | H41: =MES_FERT_COST | I41: =G41+H41 | J41: =MES_PRICE | K41: =J41-I41 | L41: =IF(K41>=0,"Yes","No")
A42: 28 | B42: =IF(28-1<=0,0,(28-1)*MES_HRS_PER_BED*WEEKS*(1+MES_DIM_PCT)^(28-1)) | C42: =28*MES_HRS_PER_BED*WEEKS*(1+MES_DIM_PCT)^28 | D42: =C42-B42 | E42: =MIN(D42,MAX(FARMER_FIELD_HOURS-B42,0)) | F42: =D42-E42 | G42: =E42*FARMER_RATE+F42*(TEMP_WORKER_COST/TEMP_WORKER_HOURS) | H42: =MES_FERT_COST | I42: =G42+H42 | J42: =MES_PRICE | K42: =J42-I42 | L42: =IF(K42>=0,"Yes","No")
A43: 29 | B43: =IF(29-1<=0,0,(29-1)*MES_HRS_PER_BED*WEEKS*(1+MES_DIM_PCT)^(29-1)) | C43: =29*MES_HRS_PER_BED*WEEKS*(1+MES_DIM_PCT)^29 | D43: =C43-B43 | E43: =MIN(D43,MAX(FARMER_FIELD_HOURS-B43,0)) | F43: =D43-E43 | G43: =E43*FARMER_RATE+F43*(TEMP_WORKER_COST/TEMP_WORKER_HOURS) | H43: =MES_FERT_COST | I43: =G43+H43 | J43: =MES_PRICE | K43: =J43-I43 | L43: =IF(K43>=0,"Yes","No")
A44: 30 | B44: =IF(30-1<=0,0,(30-1)*MES_HRS_PER_BED*WEEKS*(1+MES_DIM_PCT)^(30-1)) | C44: =30*MES_HRS_PER_BED*WEEKS*(1+MES_DIM_PCT)^30 | D44: =C44-B44 | E44: =MIN(D44,MAX(FARMER_FIELD_HOURS-B44,0)) | F44: =D44-E44 | G44: =E44*FARMER_RATE+F44*(TEMP_WORKER_COST/TEMP_WORKER_HOURS) | H44: =MES_FERT_COST | I44: =G44+H44 | J44: =MES_PRICE | K44: =J44-I44 | L44: =IF(K44>=0,"Yes","No")
A45: 31 | B45: =IF(31-1<=0,0,(31-1)*MES_HRS_PER_BED*WEEKS*(1+MES_DIM_PCT)^(31-1)) | C45: =31*MES_HRS_PER_BED*WEEKS*(1+MES_DIM_PCT)^31 | D45: =C45-B45 | E45: =MIN(D45,MAX(FARMER_FIELD_HOURS-B45,0)) | F45: =D45-E45 | G45: =E45*FARMER_RATE+F45*(TEMP_WORKER_COST/TEMP_WORKER_HOURS) | H45: =MES_FERT_COST | I45: =G45+H45 | J45: =MES_PRICE | K45: =J45-I45 | L45: =IF(K45>=0,"Yes","No")
A47: Same story: marginal cost at bed 30 (the cap) is still comfortably below the $2,700 price. Bed 31, if the cap allowed it, would still have earned about $246 -- again a fence, not the economics, ends production.
A50: Binding Constraints Check — plan grown to its economic/physical limits (10 / 20 / 30 beds)
A51: Tomatoes beds (economics-limited) | B51: 10
A52: Carrots beds (cap-limited) | B52: 20
A53: Mesclun beds (cap-limited) | B53: 30
A54: Total beds used | B54: =SUM(B51:B53)
...

Sheet P&L
A1: P&L — Convention A (Cash / Marginal Costing, continuous hourly rate — drives Solver objective)
B3: Tomatoes | C3: Carrots | D3: Mesclun | E3: Total
A4: Beds | B4: ='Solver Model'!B4 | C4: ='Solver Model'!B5 | D4: ='Solver Model'!B6 | E4: =SUM(B4:D4)
A5: Revenue ($) | B5: =B4*TOM_PRICE | C5: =C4*CAR_PRICE | D5: =D4*MES_PRICE | E5: =SUM(B5:D5)
A6: Fertilizer ($) | B6: =B4*TOM_FERT_COST | C6: =C4*CAR_FERT_COST | D6: =D4*MES_FERT_COST | E6: =SUM(B6:D6)
A8: Labor
A9: Total labor hours required | B9: =Engine!F9
A10: Farmer field hours available | B10: =FARMER_FIELD_HOURS
A11: Hours covered by farmer (free, already paid) | B11: =MIN(B9,B10)
A12: Hours requiring temp workers | B12: =MAX(B9-B10,0)
A13: Max temp labor hours available (workers x hours/worker) | B13: =MAX_TEMP_WORKERS*TEMP_WORKER_HOURS
A14: Feasible? | B14: =IF(B12>B13,"INFEASIBLE — exceeds available temp-labor hours","OK")
A15: Farmer field-hours labor cost ($, at her implied hourly rate) | B15: =B11*FARMER_RATE
A16: Temp labor cost ($, continuous hourly rate) | B16: =B12*TEMP_RATE
A18: Fixed Costs
A19: Other fixed costs ($) | B19: =FIXED_COSTS_OTHER
A22: Profit — Convention A (Solver objective) | B22: =E5-E6-B15-B16-B19
A24: P&L — Convention B (Blended-Rate Costing — reporting only, NOT the Solver objective)
A25: Total labor $ spent (same cash as Convention A) | B25: =B15+B16
A26: Total labor hours purchased (farmer field hrs + temp hrs, = total hours required) | B26: =B11+B12
A27: Blended labor rate ($/hr) | B27: =IF(B26=0,0,B25/B26)
A28: Labor cost allocated to crops at blended rate | B28: =B9*B27
A29: Profit — Convention B | B29: =E5-E6-B28-B19
A31: Convention A prices labor by the hour actually consumed: the farmer's field hours at her own implied rate (FARMER_RATE), and every hour beyond that continuously at the temp rate (TEMP_RATE) — capped at MAX_TEMP_WORKERS x TEMP_WORKER_HOURS of total availability, not hired in discrete worker-sized blocks. This is the case's published convention and is what Solver maximizes. Convention B spreads the same total labor dollars evenly across all labor hours purchased into one blended $/hr rate; it is useful for per-bed unit-economics reporting, but do not use it as the Solver objective. (A discrete, whole-worker-block costing convention is a legitimate alternative reading of this case — see the Stage 1.3 memo for that argument and the different recommendation it produces.)

Sheet Audit
A1: Audit — Six Checks
A3: Check 1 — q = 1 hand calculation (Tomatoes)
A4: Formula-based value (engine formula with q=1, linked to Inputs) | B4: =1*TOM_HRS_PER_BED*WEEKS*(1+TOM_DIM_PCT)^1
A5: Hand-arithmetic value: 1 x 2.50 x 36 x 1.10 (literal, from the case prompt) | B5: =1*2.5*36*1.1
A6: Match? | B6: =IF(ROUND(B4,6)=ROUND(B5,6),"MATCH ("&TEXT(B4,"0.00")&" hours)","MISMATCH — review Inputs vs hand figures")
A7: B5 intentionally hardcodes the case's stated figures as an independent hand check; B4 is the live formula that must reproduce it.
A9: Check 2 — Intermediate marginal cost cross-check (Tomatoes, q=10) vs Farm Profit Lab
A10: Marginal cost of bed q (model) | B10: =Engine!B24
A11: Marginal profit of bed q (model) | B11: =Engine!B26
A12: Farm Profit Lab reference value (enter on Engine!B28) | B12: =Engine!B28
A13: Match? | B13: =Engine!B29
A15: Check 3 — Solver path-dependence (start 0/0/0 vs start 20/0/0)
A16: Run 1 final beds (T / C / M) | B16: ='Solver Model'!E38&" / "&'Solver Model'!F38&" / "&'Solver Model'!G38
A17: Run 1 final profit | B17: ='Solver Model'!H38
A18: Run 2 final beds (T / C / M) | B18: ='Solver Model'!E39&" / "&'Solver Model'!F39&" / "&'Solver Model'!G39
A19: Run 2 final profit | B19: ='Solver Model'!H39
A20: Conclusion | B20: ='Solver Model'!B41
A21: Independent exhaustive verification (supplementary, not a substitute for the Solver run above): all 9,726 feasible integer combinations of (Q_TOMATOES, Q_CARROTS, Q_MESCLUN) were enumerated directly from this spec's formulas. (10, 20, 30) is the unique global maximum at $42,761.664682745... — confirmed to the same cent as this workbook's own P&L!B22 and Check 6's acceptance figure. This doesn't replace Checks 2 or 3 below (Farm Profit Lab and the actual Solver run), both of which still need to be done in Excel/the course tool, but it does establish there is no path-dependence risk to find: the global optimum is unique, so a correctly configured Solver run from any starting point should converge here.
A25: Check 4 — Check figures (constraint & feasibility reconciliation)
A26: Constraint | B26: Used | C26: Cap | D26: Status
A27: Tomatoes beds | B27: ='Solver Model'!B4 | C27: =TOM_BED_CAP | D27: =IF(B27<=C27,"OK","EXCEEDS")
A28: Carrots beds | B28: ='Solver Model'!B5 | C28: =CAR_BED_CAP | D28: =IF(B28<=C28,"OK","EXCEEDS")
A29: Mesclun beds | B29: ='Solver Model'!B6 | C29: =MES_BED_CAP | D29: =IF(B29<=C29,"OK","EXCEEDS")
A30: Total beds | B30: ='Solver Model'!B7 | C30: =TOTAL_BED_CAP | D30: =IF(B30<=C30,"OK","EXCEEDS")
A31: Temp labor hours (raw required) | B31: ='P&L'!B12 | C31: =MAX_TEMP_WORKERS*TEMP_WORKER_HOURS | D31: =IF(B31<=C31,"OK","EXCEEDS")
A32: Total labor hours | B32: =Engine!F9 | C32: =FARMER_FIELD_HOURS+MAX_TEMP_WORKERS*TEMP_WORKER_HOURS | D32: =IF(B32<=C32,"OK","EXCEEDS")
A34: Check 5 — Formulas, not pasted values
A35: All revenue, fertilizer, labor-hour, labor-cost, and profit figures on the P&L, Engine, and Solver Model sheets are live formulas referencing the Inputs sheet and the three decision cells ('Solver Model'!B4:B6) — confirm by selecting any output cell and reading the formula bar. The only intentionally hardcoded numbers in the workbook are: (a) the literal 'by-hand' check in Audit!B5 (used only to verify the engine formula, per Check 1), and (b) the two Solver run starting points (0/0/0 and 20/0/0) entered as Solver's initial seed values in 'Solver Model'!B38:D39 before optimization.
A41: Spot list
A42: Cell | B42: Sheet | C42: Contains
A43: B22 (Profit_ConventionA) | B43: P&L | C43: Live formula
A44: B19 (Objective_Profit, linked) | B44: Solver Model | C44: Live formula (link)
A45: F9 (Total Labor Hours) | B45: Engine | C45: Live formula
A46: B12 (Temp labor hours required, raw) | B46: P&L | C46: Live formula
A48: Check 6 — Acceptance figure vs. the case's published answer (tolerance $0.01)
A49: Published profit (Tomatoes=10, Carrots=20, Mesclun=30) | B49: 42761.66
A50: Model profit at these beds (P&L, Convention A) | B50: ='P&L'!B22
A51: Difference | B51: =B50-B49
A52: Within tolerance? | B52: =IF(ABS(B51)<=0.01,"MATCH (within $0.01)","REVIEW — outside tolerance")
A53: B49 is hardcoded from the case's published figures (see the Stage 1.2 review), not derived from this workbook — it is the external acceptance target Check 2 and this check verify against, per the review's note that a check without a target only proves the sheet computed something, not that it computed the right thing.
