Workbook

Sheet Inputs
A1: Perfect Competition Farm — Model Inputs
A3: Season & Farm
A4: Season length (weeks) | B4: 36
A5: Total beds available (16 beds x 4 plots) | B5: 64
A6: Beds per plot | B6: 16
A7: Number of plots | B7: 4
A8: Fixed costs ($/season) | B8: 20000
A10: Farmer Labor
A11: Farmer salary ($/season) | B11: 50000
A12: Farmer total season hours (implied) | B12: 1440
A13: Farmer share of time in field | B13: 0.5
A14: Farmer field hours (season) | B14: =B12*B13 -> 720
A15: Farmer implied hourly rate ($/hr) | B15: =B11/B12 -> 34.722222
A17: Temporary Workers
A18: Cost per temp worker ($/season) | B18: 25000
A19: Hours per temp worker (season) | B19: 1440
A20: Temp worker implied hourly rate ($/hr) | B20: =B18/B19 -> 17.361111
A21: Max temp workers allowed | B21: 4
A23: Crop Economics
A24: Crop | B24: Max beds | C24: Price $/bed | D24: Labor hrs/wk/bed | E24: Fertilizer $/bed | F24: Diminishing returns %/bed
A25: Tomatoes | B25: 20 | C25: 8800 | D25: 2.5 | E25: 880 | F25: 0.1
A26: Carrots | B26: 20 | C26: 2094 | D26: 0.833 | E26: 440 | F26: 0.025
A27: Mesclun | B27: 30 | C27: 2700 | D27: 1.25 | E27: 880 | F27: 0.0125
A29: All figures above are given in the case data (blue = hardcoded input). Farmer field hours and hourly rates are derived by formula from the salary/hours/share inputs.

Sheet Solver Model
A1: Solver Model — Decision Variables & Settings
A3: Decision Cells (Solver's Changing Variable Cells)
A4: Beds — Tomatoes | B4: 10
A5: Beds — Carrots | B5: 19
A6: Beds — Mesclun | B6: 28
A7: Total beds used | B7: =B4+B5+B6 -> 57
A8: Temp workers required (raw, linked from P&L) | B8: ='P&L'!B13 -> 3
A10: Constraint Check
A11: Tomatoes beds <= max (20) | B11: =IF(B4<=Inputs!B25,"OK","EXCEEDS") -> OK
A12: Carrots beds <= max (20) | B12: =IF(B5<=Inputs!B26,"OK","EXCEEDS") -> OK
A13: Mesclun beds <= max (30) | B13: =IF(B6<=Inputs!B27,"OK","EXCEEDS") -> OK
A14: Total beds <= cap (64) | B14: =IF(B7<=Inputs!B5,"OK","EXCEEDS") -> OK
A15: Temp workers <= max (4) | B15: =IF(B8<=Inputs!B21,"OK","EXCEEDS") -> OK
A16: Beds are non-negative integers — enforced in Solver via an "int" constraint on B4:B6 (see setup below).
A18: Objective
A19: Profit (maximize) — linked from P&L Convention A | B19: ='P&L'!B22 -> 16586
A21: Solver Setup (Data > Analysis > Solver)
A22: Set Objective: 'Solver Model'!$B$19 (Profit, Convention A) -> To: Max
A23: By Changing Variable Cells: 'Solver Model'!$B$4:$B$6 (Beds - Tomatoes, Carrots, Mesclun)
A24: Subject to the Constraints:
A25: $B$4 <= Inputs!$B$25 (Tomatoes <= 20 beds)
A26: $B$5 <= Inputs!$B$26 (Carrots <= 20 beds)
A27: $B$6 <= Inputs!$B$27 (Mesclun <= 30 beds)
A28: $B$7 <= Inputs!$B$5 (Total beds <= 64)
A29: $B$8 <= Inputs!$B$21 (Temp workers <= 4)
A30: $B$4:$B$6 = integer
A31: $B$4:$B$6 >= 0
A32: Solving Method: GRG Nonlinear
... A36: Run Log — Path-Dependence Check
A37: Run | B37: Start T | C37: Start C | D37: Start M | E37: Final T | F37: Final C | G37: Final M | H37: Final Profit | I37: Notes
A38: Run 1 | B38: 0 | C38: 0 | D38: 0 | E38: 13 | F38: 10 | G38: 30 | H38: 4100
A39: Run 2 | B39: 20 | C39: 0 | D39: 0 | E39: 10 | F39: 19 | G39: 28 | H39: 16586
A41: Path-dependence conclusion | B41: =IF(OR(H38="",H39=""),"Pending — run Solver from both starting points above and paste the Final results (E:H) for Run 1 and Run 2.",IF(ROUND(H38,2)=ROUND(H39,2),"Same optimum reached from both starts — no path-dependence detected in this instance.","Path-dependent: the two starts converge to different local optima (Run 1 profit "&TEXT(H38,"$#,##0")&" vs Run 2 profit "&TEXT(H39,"$#,##0")&"). Report the higher-profit run; the (1+dim%)^q term makes the objective non-convex, so GRG Nonlinear is only guaranteed to find a local optimum.")) -> Path-dependent: the two starts converge to different local optima (Run 1 profit $4,100 vs Run 2 profit $16,586). Report the higher-profit run; the (1+dim%)^q term makes the objective non-convex, so GRG Nonlinear is only guaranteed to find a local optimum.
A43: Independent reference (not a Solver output)
A44: A brute-force search of all feasible integer bed combinations (computed outside Excel, for sanity-checking only) finds a global optimum near Tomatoes=10, Carrots=19, Mesclun=28 (57 beds, 3 temp workers, Profit approx. $16,586). If neither Solver run lands in that range, re-seed Solver from a third start (e.g. these values).

Sheet Engine
A1: Engine — Labor Hours Formula (the one formula that drives the model)
A3: Labor hours for q beds = q x hrs-per-week-per-bed x 36 weeks x (1 + diminishing%)^q
A5: Crop | B5: Beds used (q) | C5: Labor hrs/wk/bed | D5: Season weeks | E5: Diminishing %/bed | F5: Labor Hours Required
A6: Tomatoes | B6: ='Solver Model'!B4 -> 10 | C6: =Inputs!D25 -> 2.5 | D6: =Inputs!B4 -> 36 | E6: =Inputs!F25 -> 0.1 | F6: =B6*C6*D6*(1+E6)^B6 -> 2334.3682
A7: Carrots | B7: ='Solver Model'!B5 -> 19 | C7: =Inputs!D26 -> 0.833 | D7: =Inputs!B4 -> 36 | E7: =Inputs!F26 -> 0.025 | F7: =B7*C7*D7*(1+E7)^B7 -> 910.86611
A8: Mesclun | B8: ='Solver Model'!B6 -> 28 | C8: =Inputs!D27 -> 1.25 | D8: =Inputs!B4 -> 36 | E8: =Inputs!F27 -> 0.0125 | F8: =B8*C8*D8*(1+E8)^B8 -> 1784.1503
A9: Total | F9: =SUM(F6:F8) -> 5029.3846
A11: Marginal Cost Explorer — audit check 2 (intermediate marginal cost, matches Farm Profit Lab convention)
A12: Crop tested | B12: Tomatoes
A13: Bed count tested (q) — must be >= 1 | B13: 10
A14: Labor hrs/wk/bed | B14: =Inputs!D25 -> 2.5
A15: Diminishing %/bed | B15: =Inputs!F25 -> 0.1
A16: Labor hours at q | B16: =B13*B14*Inputs!B4*(1+B15)^B13 -> 2334.3682
A17: Labor hours at q-1 | B17: =(B13-1)*B14*Inputs!B4*(1+B15)^(B13-1) -> 1909.9376
A18: Marginal labor hours (delta for the q-th bed) | B18: =B16-B17 -> 424.43058
A19: Free hours remaining before this bed (farmer, isolated view) | B19: =MAX(Inputs!B14-B17,0) -> 0
A20: Free hours used by this bed | B20: =MIN(B18,B19) -> 0
A21: Paid (temp-rate) hours for this bed | B21: =B18-B20 -> 424.43058
A22: Marginal labor $ (paid hours x temp rate) | B22: =B21*(Inputs!B18/Inputs!B19) -> 7368.5865
A23: Marginal fertilizer $ (constant per bed) | B23: =Inputs!E25 -> 880
A24: Marginal cost of the q-th bed (labor + fertilizer) | B24: =B22+B23 -> 8248.5865
A25: Marginal revenue (price per bed) | B25: =Inputs!C25 -> 8800
A26: Marginal profit of the q-th bed | B26: =B25-B24 -> 551.41347
A28: Farm Profit Lab reference value (paste here)
A29: Match? | B29: =IF(B28="","Pending — paste Farm Profit Lab figure",IF(ROUND(B28,2)=ROUND(B24,2),"MATCH","REVIEW — differs from Farm Profit Lab")) -> Pending — paste Farm Profit Lab figure

Sheet Marginal Analysis
A1: Marginal Analysis — Where Marginal Cost Crosses Price
A3: Convention: each crop is evaluated on its own labor-hours curve as if it alone drew on the farmer's 720 free field hours before any paid labor begins. Hours beyond that free allowance are costed continuously at the temp-worker rate ($25,000 / 1,440 hrs = $17.36/hr), bed by bed -- the smooth convention this case's marginal-cost checks (and the Farm Profit Lab cross-check) use. This differs from the Solver / P&L sheets, which cost temp labor in true discrete $25,000-per-worker hiring blocks for the actual cash plan -- see the note at the bottom of this sheet for why that difference matters.
A7: Tomatoes (price = Inputs!C25)
A8: q | B8: Cum. hours thru q-1 | C8: Cum. hours thru q | D8: Marginal hours | E8: Free hours (farmer) | F8: Paid hours (temp) | G8: Marginal labor $ | H8: Marginal fertilizer $ | I8: Marginal cost | J8: Price | K8: Marginal profit | L8: Profitable?
A9: 1 | B9: =IF(1-1<=0,0,(1-1)*Inputs!$D$25*Inputs!$B$4*(1+Inputs!$F$25)^(1-1)) -> 0 | C9: =1*Inputs!$D$25*Inputs!$B$4*(1+Inputs!$F$25)^1 -> 99 | D9: =C9-B9 -> 99 | E9: =MIN(D9,MAX(Inputs!$B$14-B9,0)) -> 99 | F9: =D9-E9 -> 0 | G9: =F9*(Inputs!$B$18/Inputs!$B$19) -> 0 | H9: =Inputs!$E$25 -> 880 | I9: =G9+H9 -> 880 | J9: =Inputs!$C$25 -> 8800 | K9: =J9-I9 -> 7920 | L9: =IF(K9>=0,"Yes","No") -> Yes
A10: 2 | B10: =IF(2-1<=0,0,(2-1)*Inputs!$D$25*Inputs!$B$4*(1+Inputs!$F$25)^(2-1)) -> 99 | C10: =2*Inputs!$D$25*Inputs!$B$4*(1+Inputs!$F$25)^2 -> 217.8 | D10: =C10-B10 -> 118.8 | E10: =MIN(D10,MAX(Inputs!$B$14-B10,0)) -> 118.8 | F10: =D10-E10 -> 0 | G10: =F10*(Inputs!$B$18/Inputs!$B$19) -> 0 | H10: =Inputs!$E$25 -> 880 | I10: =G10+H10 -> 880 | J10: =Inputs!$C$25 -> 8800 | K10: =J10-I10 -> 7920 | L10: =IF(K10>=0,"Yes","No") -> Yes
A11: 3 | B11: =IF(3-1<=0,0,(3-1)*Inputs!$D$25*Inputs!$B$4*(1+Inputs!$F$25)^(3-1)) -> 217.8 | C11: =3*Inputs!$D$25*Inputs!$B$4*(1+Inputs!$F$25)^3 -> 359.37 | D11: =C11-B11 -> 141.57 | E11: =MIN(D11,MAX(Inputs!$B$14-B11,0)) -> 141.57 | F11: =D11-E11 -> 0 | G11: =F11*(Inputs!$B$18/Inputs!$B$19) -> 0 | H11: =Inputs!$E$25 -> 880 | I11: =G11+H11 -> 880 | J11: =Inputs!$C$25 -> 8800 | K11: =J11-I11 -> 7920 | L11: =IF(K11>=0,"Yes","No") -> Yes
A12: 4 | B12: =IF(4-1<=0,0,(4-1)*Inputs!$D$25*Inputs!$B$4*(1+Inputs!$F$25)^(4-1)) -> 359.37 | C12: =4*Inputs!$D$25*Inputs!$B$4*(1+Inputs!$F$25)^4 -> 527.076 | D12: =C12-B12 -> 167.706 | E12: =MIN(D12,MAX(Inputs!$B$14-B12,0)) -> 167.706 | F12: =D12-E12 -> 0 | G12: =F12*(Inputs!$B$18/Inputs!$B$19) -> 0 | H12: =Inputs!$E$25 -> 880 | I12: =G12+H12 -> 880 | J12: =Inputs!$C$25 -> 8800 | K12: =J12-I12 -> 7920 | L12: =IF(K12>=0,"Yes","No") -> Yes
A13: 5 | B13: =IF(5-1<=0,0,(5-1)*Inputs!$D$25*Inputs!$B$4*(1+Inputs!$F$25)^(5-1)) -> 527.076 | C13: =5*Inputs!$D$25*Inputs!$B$4*(1+Inputs!$F$25)^5 -> 724.7295 | D13: =C13-B13 -> 197.6535 | E13: =MIN(D13,MAX(Inputs!$B$14-B13,0)) -> 192.924 | F13: =D13-E13 -> 4.7295 | G13: =F13*(Inputs!$B$18/Inputs!$B$19) -> 82.109375 | H13: =Inputs!$E$25 -> 880 | I13: =G13+H13 -> 962.10938 | J13: =Inputs!$C$25 -> 8800 | K13: =J13-I13 -> 7837.8906 | L13: =IF(K13>=0,"Yes","No") -> Yes
A14: 6 | B14: =IF(6-1<=0,0,(6-1)*Inputs!$D$25*Inputs!$B$4*(1+Inputs!$F$25)^(6-1)) -> 724.7295 | C14: =6*Inputs!$D$25*Inputs!$B$4*(1+Inputs!$F$25)^6 -> 956.64294 | D14: =C14-B14 -> 231.91344 | E14: =MIN(D14,MAX(Inputs!$B$14-B14,0)) -> 0 | F14: =D14-E14 -> 231.91344 | G14: =F14*(Inputs!$B$18/Inputs!$B$19) -> 4026.275 | H14: =Inputs!$E$25 -> 880 | I14: =G14+H14 -> 4906.275 | J14: =Inputs!$C$25 -> 8800 | K14: =J14-I14 -> 3893.725 | L14: =IF(K14>=0,"Yes","No") -> Yes
A15: 7 | B15: =IF(7-1<=0,0,(7-1)*Inputs!$D$25*Inputs!$B$4*(1+Inputs!$F$25)^(7-1)) -> 956.64294 | C15: =7*Inputs!$D$25*Inputs!$B$4*(1+Inputs!$F$25)^7 -> 1227.6918 | D15: =C15-B15 -> 271.04883 | E15: =MIN(D15,MAX(Inputs!$B$14-B15,0)) -> 0 | F15: =D15-E15 -> 271.04883 | G15: =F15*(Inputs!$B$18/Inputs!$B$19) -> 4705.7089 | H15: =Inputs!$E$25 -> 880 | I15: =G15+H15 -> 5585.7089 | J15: =Inputs!$C$25 -> 8800 | K15: =J15-I15 -> 3214.2911 | L15: =IF(K15>=0,"Yes","No") -> Yes
A16: 8 | B16: =IF(8-1<=0,0,(8-1)*Inputs!$D$25*Inputs!$B$4*(1+Inputs!$F$25)^(8-1)) -> 1227.6918 | C16: =8*Inputs!$D$25*Inputs!$B$4*(1+Inputs!$F$25)^8 -> 1543.3839 | D16: =C16-B16 -> 315.69217 | E16: =MIN(D16,MAX(Inputs!$B$14-B16,0)) -> 0 | F16: =D16-E16 -> 315.69217 | G16: =F16*(Inputs!$B$18/Inputs!$B$19) -> 5480.7668 | H16: =Inputs!$E$25 -> 880 | I16: =G16+H16 -> 6360.7668 | J16: =Inputs!$C$25 -> 8800 | K16: =J16-I16 -> 2439.2332 | L16: =IF(K16>=0,"Yes","No") -> Yes
A17: 9 | B17: =IF(9-1<=0,0,(9-1)*Inputs!$D$25*Inputs!$B$4*(1+Inputs!$F$25)^(9-1)) -> 1543.3839 | C17: =9*Inputs!$D$25*Inputs!$B$4*(1+Inputs!$F$25)^9 -> 1909.9376 | D17: =C17-B17 -> 366.55369 | E17: =MIN(D17,MAX(Inputs!$B$14-B17,0)) -> 0 | F17: =D17-E17 -> 366.55369 | G17: =F17*(Inputs!$B$18/Inputs!$B$19) -> 6363.7793 | H17: =Inputs!$E$25 -> 880 | I17: =G17+H17 -> 7243.7793 | J17: =Inputs!$C$25 -> 8800 | K17: =J17-I17 -> 1556.2207 | L17: =IF(K17>=0,"Yes","No") -> Yes
A18: 10 | B18: =IF(10-1<=0,0,(10-1)*Inputs!$D$25*Inputs!$B$4*(1+Inputs!$F$25)^(10-1)) -> 1909.9376 | C18: =10*Inputs!$D$25*Inputs!$B$4*(1+Inputs!$F$25)^10 -> 2334.3682 | D18: =C18-B18 -> 424.43058 | E18: =MIN(D18,MAX(Inputs!$B$14-B18,0)) -> 0 | F18: =D18-E18 -> 424.43058 | G18: =F18*(Inputs!$B$18/Inputs!$B$19) -> 7368.5865 | H18: =Inputs!$E$25 -> 880 | I18: =G18+H18 -> 8248.5865 | J18: =Inputs!$C$25 -> 8800 | K18: =J18-I18 -> 551.41347 | L18: =IF(K18>=0,"Yes","No") -> Yes
A19: 11 | B19: =IF(11-1<=0,0,(11-1)*Inputs!$D$25*Inputs!$B$4*(1+Inputs!$F$25)^(11-1)) -> 2334.3682 | C19: =11*Inputs!$D$25*Inputs!$B$4*(1+Inputs!$F$25)^11 -> 2824.5855 | D19: =C19-B19 -> 490.21732 | E19: =MIN(D19,MAX(Inputs!$B$14-B19,0)) -> 0 | F19: =D19-E19 -> 490.21732 | G19: =F19*(Inputs!$B$18/Inputs!$B$19) -> 8510.7174 | H19: =Inputs!$E$25 -> 880 | I19: =G19+H19 -> 9390.7174 | J19: =Inputs!$C$25 -> 8800 | K19: =J19-I19 -> -590.71745 | L19: =IF(K19>=0,"Yes","No") -> No
A20: 12 | B20: =IF(12-1<=0,0,(12-1)*Inputs!$D$25*Inputs!$B$4*(1+Inputs!$F$25)^(12-1)) -> 2824.5855 | C20: =12*Inputs!$D$25*Inputs!$B$4*(1+Inputs!$F$25)^12 -> 3389.5026 | D20: =C20-B20 -> 564.91711 | E20: =MIN(D20,MAX(Inputs!$B$14-B20,0)) -> 0 | F20: =D20-E20 -> 564.91711 | G20: =F20*(Inputs!$B$18/Inputs!$B$19) -> 9807.5887 | H20: =Inputs!$E$25 -> 880 | I20: =G20+H20 -> 10687.589 | J20: =Inputs!$C$25 -> 8800 | K20: =J20-I20 -> -1887.5887 | L20: =IF(K20>=0,"Yes","No") -> No
A22: Beds 1-4 draw only on the farmer's already-paid-for hours, so marginal cost sits near the $880 fertilizer floor. The farmer's 720 hours run out partway through bed 5, so bed 6 is the first bed priced entirely at the $17.36/hr temp rate -- marginal cost jumps sharply there rather than climbing smoothly from bed 1. Marginal cost stays below the $8,800 price through bed 10 ($8,249) and crosses above it at bed 11 ($9,391) -- tomatoes are self-limiting at 10 beds on economics alone, regardless of the bed cap.
A26: Carrots (price = Inputs!C26) -- approaching the 20-bed cap
A27: q | B27: Cum. hours thru q-1 | C27: Cum. hours thru q | D27: Marginal hours | E27: Free hours (farmer) | F27: Paid hours (temp) | G27: Marginal labor $ | H27: Marginal fertilizer $ | I27: Marginal cost | J27: Price | K27: Marginal profit | L27: Profitable?
A28: 16 | B28: =IF(16-1<=0,0,(16-1)*Inputs!$D$26*Inputs!$B$4*(1+Inputs!$F$26)^(16-1)) -> 651.47348 | C28: =16*Inputs!$D$26*Inputs!$B$4*(1+Inputs!$F$26)^16 -> 712.27767 | D28: =C28-B28 -> 60.804192 | E28: =MIN(D28,MAX(Inputs!$B$14-B28,0)) -> 60.804192 | F28: =D28-E28 -> 0 | G28: =F28*(Inputs!$B$18/Inputs!$B$19) -> 0 | H28: =Inputs!$E$26 -> 440 | I28: =G28+H28 -> 440 | J28: =Inputs!$C$26 -> 2094 | K28: =J28-I28 -> 1654 | L28: =IF(K28>=0,"Yes","No") -> Yes
A29: 17 | B29: =IF(17-1<=0,0,(17-1)*Inputs!$D$26*Inputs!$B$4*(1+Inputs!$F$26)^(17-1)) -> 712.27767 | C29: =17*Inputs!$D$26*Inputs!$B$4*(1+Inputs!$F$26)^17 -> 775.7149 | D29: =C29-B29 -> 63.43723 | E29: =MIN(D29,MAX(Inputs!$B$14-B29,0)) -> 7.7223272 | F29: =D29-E29 -> 55.714903 | G29: =F29*(Inputs!$B$18/Inputs!$B$19) -> 967.27262 | H29: =Inputs!$E$26 -> 440 | I29: =G29+H29 -> 1407.2726 | J29: =Inputs!$C$26 -> 2094 | K29: =J29-I29 -> 686.72738 | L29: =IF(K29>=0,"Yes","No") -> Yes
A30: 18 | B30: =IF(18-1<=0,0,(18-1)*Inputs!$D$26*Inputs!$B$4*(1+Inputs!$F$26)^(18-1)) -> 775.7149 | C30: =18*Inputs!$D$26*Inputs!$B$4*(1+Inputs!$F$26)^18 -> 841.87882 | D30: =C30-B30 -> 66.163918 | E30: =MIN(D30,MAX(Inputs!$B$14-B30,0)) -> 0 | F30: =D30-E30 -> 66.163918 | G30: =F30*(Inputs!$B$18/Inputs!$B$19) -> 1148.6791 | H30: =Inputs!$E$26 -> 440 | I30: =G30+H30 -> 1588.6791 | J30: =Inputs!$C$26 -> 2094 | K30: =J30-I30 -> 505.32086 | L30: =IF(K30>=0,"Yes","No") -> Yes
A31: 19 | B31: =IF(19-1<=0,0,(19-1)*Inputs!$D$26*Inputs!$B$4*(1+Inputs!$F$26)^(19-1)) -> 841.87882 | C31: =19*Inputs!$D$26*Inputs!$B$4*(1+Inputs!$F$26)^19 -> 910.86611 | D31: =C31-B31 -> 68.987292 | E31: =MIN(D31,MAX(Inputs!$B$14-B31,0)) -> 0 | F31: =D31-E31 -> 68.987292 | G31: =F31*(Inputs!$B$18/Inputs!$B$19) -> 1197.696 | H31: =Inputs!$E$26 -> 440 | I31: =G31+H31 -> 1637.696 | J31: =Inputs!$C$26 -> 2094 | K31: =J31-I31 -> 456.30395 | L31: =IF(K31>=0,"Yes","No") -> Yes
A32: 20 | B32: =IF(20-1<=0,0,(20-1)*Inputs!$D$26*Inputs!$B$4*(1+Inputs!$F$26)^(20-1)) -> 910.86611 | C32: =20*Inputs!$D$26*Inputs!$B$4*(1+Inputs!$F$26)^20 -> 982.7766 | D32: =C32-B32 -> 71.910483 | E32: =MIN(D32,MAX(Inputs!$B$14-B32,0)) -> 0 | F32: =D32-E32 -> 71.910483 | G32: =F32*(Inputs!$B$18/Inputs!$B$19) -> 1248.4459 | H32: =Inputs!$E$26 -> 440 | I32: =G32+H32 -> 1688.4459 | J32: =Inputs!$C$26 -> 2094 | K32: =J32-I32 -> 405.55412 | L32: =IF(K32>=0,"Yes","No") -> Yes
A33: 21 | B33: =IF(21-1<=0,0,(21-1)*Inputs!$D$26*Inputs!$B$4*(1+Inputs!$F$26)^(21-1)) -> 982.7766 | C33: =21*Inputs!$D$26*Inputs!$B$4*(1+Inputs!$F$26)^21 -> 1057.7133 | D33: =C33-B33 -> 74.936715 | E33: =MIN(D33,MAX(Inputs!$B$14-B33,0)) -> 0 | F33: =D33-E33 -> 74.936715 | G33: =F33*(Inputs!$B$18/Inputs!$B$19) -> 1300.9846 | H33: =Inputs!$E$26 -> 440 | I33: =G33+H33 -> 1740.9846 | J33: =Inputs!$C$26 -> 2094 | K33: =J33-I33 -> 353.01536 | L33: =IF(K33>=0,"Yes","No") -> Yes
A35: Marginal cost is still well below the $2,094 price at bed 20, the last bed the 20-bed cap allows. Bed 21 (blocked by the cap) would still have earned about $353 -- the cap, not the economics, stops production here. That $353 is the shadow value of one more bed of ground.
A38: Mesclun (price = Inputs!C27) -- approaching the 30-bed cap
A39: q | B39: Cum. hours thru q-1 | C39: Cum. hours thru q | D39: Marginal hours | E39: Free hours (farmer) | F39: Paid hours (temp) | G39: Marginal labor $ | H39: Marginal fertilizer $ | I39: Marginal cost | J39: Price | K39: Marginal profit | L39: Profitable?
A40: 26 | B40: =IF(26-1<=0,0,(26-1)*Inputs!$D$27*Inputs!$B$4*(1+Inputs!$F$27)^(26-1)) -> 1534.7171 | C40: =26*Inputs!$D$27*Inputs!$B$4*(1+Inputs!$F$27)^26 -> 1616.0571 | D40: =C40-B40 -> 81.340004 | E40: =MIN(D40,MAX(Inputs!$B$14-B40,0)) -> 0 | F40: =D40-E40 -> 81.340004 | G40: =F40*(Inputs!$B$18/Inputs!$B$19) -> 1412.1528 | H40: =Inputs!$E$27 -> 880 | I40: =G40+H40 -> 2292.1528 | J40: =Inputs!$C$27 -> 2700 | K40: =J40-I40 -> 407.84715 | L40: =IF(K40>=0,"Yes","No") -> Yes
A41: 27 | B41: =IF(27-1<=0,0,(27-1)*Inputs!$D$27*Inputs!$B$4*(1+Inputs!$F$27)^(27-1)) -> 1616.0571 | C41: =27*Inputs!$D$27*Inputs!$B$4*(1+Inputs!$F$27)^27 -> 1699.1908 | D41: =C41-B41 -> 83.133705 | E41: =MIN(D41,MAX(Inputs!$B$14-B41,0)) -> 0 | F41: =D41-E41 -> 83.133705 | G41: =F41*(Inputs!$B$18/Inputs!$B$19) -> 1443.2935 | H41: =Inputs!$E$27 -> 880 | I41: =G41+H41 -> 2323.2935 | J41: =Inputs!$C$27 -> 2700 | K41: =J41-I41 -> 376.70652 | L41: =IF(K41>=0,"Yes","No") -> Yes
A42: 28 | B42: =IF(28-1<=0,0,(28-1)*Inputs!$D$27*Inputs!$B$4*(1+Inputs!$F$27)^(28-1)) -> 1699.1908 | C42: =28*Inputs!$D$27*Inputs!$B$4*(1+Inputs!$F$27)^28 -> 1784.1503 | D42: =C42-B42 -> 84.959538 | E42: =MIN(D42,MAX(Inputs!$B$14-B42,0)) -> 0 | F42: =D42-E42 -> 84.959538 | G42: =F42*(Inputs!$B$18/Inputs!$B$19) -> 1474.992 | H42: =Inputs!$E$27 -> 880 | I42: =G42+H42 -> 2354.992 | J42: =Inputs!$C$27 -> 2700 | K42: =J42-I42 -> 345.00802 | L42: =IF(K42>=0,"Yes","No") -> Yes
A43: 29 | B43: =IF(29-1<=0,0,(29-1)*Inputs!$D$27*Inputs!$B$4*(1+Inputs!$F$27)^(29-1)) -> 1784.1503 | C43: =29*Inputs!$D$27*Inputs!$B$4*(1+Inputs!$F$27)^29 -> 1870.9683 | D43: =C43-B43 -> 86.818028 | E43: =MIN(D43,MAX(Inputs!$B$14-B43,0)) -> 0 | F43: =D43-E43 -> 86.818028 | G43: =F43*(Inputs!$B$18/Inputs!$B$19) -> 1507.2574 | H43: =Inputs!$E$27 -> 880 | I43: =G43+H43 -> 2387.2574 | J43: =Inputs!$C$27 -> 2700 | K43: =J43-I43 -> 312.74257 | L43: =IF(K43>=0,"Yes","No") -> Yes
A44: 30 | B44: =IF(30-1<=0,0,(30-1)*Inputs!$D$27*Inputs!$B$4*(1+Inputs!$F$27)^(30-1)) -> 1870.9683 | C44: =30*Inputs!$D$27*Inputs!$B$4*(1+Inputs!$F$27)^30 -> 1959.678 | D44: =C44-B44 -> 88.709705 | E44: =MIN(D44,MAX(Inputs!$B$14-B44,0)) -> 0 | F44: =D44-E44 -> 88.709705 | G44: =F44*(Inputs!$B$18/Inputs!$B$19) -> 1540.0991 | H44: =Inputs!$E$27 -> 880 | I44: =G44+H44 -> 2420.0991 | J44: =Inputs!$C$27 -> 2700 | K44: =J44-I44 -> 279.90095 | L44: =IF(K44>=0,"Yes","No") -> Yes
A45: 31 | B45: =IF(31-1<=0,0,(31-1)*Inputs!$D$27*Inputs!$B$4*(1+Inputs!$F$27)^(31-1)) -> 1959.678 | C45: =31*Inputs!$D$27*Inputs!$B$4*(1+Inputs!$F$27)^31 -> 2050.3131 | D45: =C45-B45 -> 90.635109 | E45: =MIN(D45,MAX(Inputs!$B$14-B45,0)) -> 0 | F45: =D45-E45 -> 90.635109 | G45: =F45*(Inputs!$B$18/Inputs!$B$19) -> 1573.5262 | H45: =Inputs!$E$27 -> 880 | I45: =G45+H45 -> 2453.5262 | J45: =Inputs!$C$27 -> 2700 | K45: =J45-I45 -> 246.4738 | L45: =IF(K45>=0,"Yes","No") -> Yes
A47: Same story: marginal cost at bed 30 (the cap) is still comfortably below the $2,700 price. Bed 31, if the cap allowed it, would still have earned about $246 -- again a fence, not the economics, ends production.
A50: Binding Constraints Check — plan grown to its economic/physical limits (10 / 20 / 30 beds)
A51: Tomatoes beds (economics-limited) | B51: 10
A52: Carrots beds (cap-limited) | B52: 20
A53: Mesclun beds (cap-limited) | B53: 30
A54: Total beds used | B54: =SUM(B51:B53) -> 60
...

Sheet P&L
A1: P&L — Convention A (Cash / Marginal Costing — drives Solver objective)
B3: Tomatoes | C3: Carrots | D3: Mesclun | E3: Total
A4: Beds | B4: ='Solver Model'!B4 -> 10 | C4: ='Solver Model'!B5 -> 19 | D4: ='Solver Model'!B6 -> 28 | E4: =SUM(B4:D4) -> 57
A5: Revenue ($) | B5: =B4*Inputs!C25 -> 88000 | C5: =C4*Inputs!C26 -> 39786 | D5: =D4*Inputs!C27 -> 75600 | E5: =SUM(B5:D5) -> 203386
A6: Fertilizer ($) | B6: =B4*Inputs!E25 -> 8800 | C6: =C4*Inputs!E26 -> 8360 | D6: =D4*Inputs!E27 -> 24640 | E6: =SUM(B6:D6) -> 41800
A8: Labor
A9: Total labor hours required | B9: =Engine!F9 -> 5029.3846
A10: Farmer field hours available | B10: =Inputs!B14 -> 720
A11: Hours covered by farmer (free, already paid) | B11: =MIN(B9,B10) -> 720
A12: Hours requiring temp workers | B12: =MAX(B9-B10,0) -> 4309.3846
A13: Workers required (raw, uncapped) | B13: =ROUNDUP(B12/Inputs!B19,0) -> 3
A14: Feasible? | B14: =IF(B13>Inputs!B21,"INFEASIBLE — exceeds 4 workers","OK") -> OK
A15: Workers hired (capped at max 4) | B15: =MIN(B13,Inputs!B21) -> 3
A16: Temp labor cost ($) | B16: =B15*Inputs!B18 -> 75000
A18: Fixed Costs
A19: Farmer salary ($, paid regardless of hours used) | B19: =Inputs!B11 -> 50000
A20: Other fixed costs ($) | B20: =Inputs!B8 -> 20000
A22: Profit — Convention A (Solver objective) | B22: =E5-E6-B16-B19-B20 -> 16586
A24: P&L — Convention B (Blended-Rate Costing — reporting only, NOT the Solver objective)
A25: Total labor $ spent (same cash as Convention A) | B25: =B19+B16 -> 125000
A26: Total labor hours purchased (farmer field hrs + hired temp hrs) | B26: =B10+B15*Inputs!B19 -> 5040
A27: Blended labor rate ($/hr) | B27: =IF(B26=0,0,B25/B26) -> 24.801587
A28: Labor cost allocated to crops at blended rate | B28: =B9*B27 -> 124736.72
A29: Profit — Convention B | B29: =E5-E6-B28-B20 -> 16849.278
A31: Convention A treats the farmer's 720 field hours as already paid for (sunk in her $50,000 salary) and adds cost only when temp workers must be hired, in stepped $25,000 / 1,440-hour blocks — this is the true incremental cash cost and is what Solver maximizes. Convention B spreads all labor dollars (farmer + temp) evenly across all labor hours purchased into one blended $/hr rate; it is useful for per-bed unit-economics reporting, but it disguises the stepped, lumpy nature of the true cost — do not use it as the Solver objective.

Sheet Audit
A1: Audit — Five Checks
A3: Check 1 — q = 1 hand calculation (Tomatoes)
A4: Formula-based value (engine formula with q=1, linked to Inputs) | B4: =1*Inputs!D25*Inputs!B4*(1+Inputs!F25)^1 -> 99
A5: Hand-arithmetic value: 1 x 2.50 x 36 x 1.10 (literal, from the case prompt) | B5: =1*2.5*36*1.1 -> 99
A6: Match? | B6: =IF(ROUND(B4,6)=ROUND(B5,6),"MATCH ("&TEXT(B4,"0.00")&" hours)","MISMATCH — review Inputs vs hand figures") -> MATCH (99.00 hours)
A7: B5 intentionally hardcodes the case's stated figures as an independent hand check; B4 is the live formula that must reproduce it.
A9: Check 2 — Intermediate marginal cost cross-check (Tomatoes, q=10) vs Farm Profit Lab
A10: Marginal cost of bed q (model) | B10: =Engine!B24 -> 8248.5865
A11: Marginal profit of bed q (model) | B11: =Engine!B26 -> 551.41347
A12: Farm Profit Lab reference value (enter on Engine!B28) | B12: =Engine!B28 -> 0
A13: Match? | B13: =Engine!B29 -> Pending — paste Farm Profit Lab figure
A15: Check 3 — Solver path-dependence (start 0/0/0 vs start 20/0/0)
A16: Run 1 final beds (T / C / M) | B16: ='Solver Model'!E38&" / "&'Solver Model'!F38&" / "&'Solver Model'!G38 -> 13 / 10 / 30
A17: Run 1 final profit | B17: ='Solver Model'!H38 -> 4100
A18: Run 2 final beds (T / C / M) | B18: ='Solver Model'!E39&" / "&'Solver Model'!F39&" / "&'Solver Model'!G39 -> 10 / 19 / 28
A19: Run 2 final profit | B19: ='Solver Model'!H39 -> 16586
A20: Conclusion | B20: ='Solver Model'!B41 -> Path-dependent: the two starts converge to different local optima (Run 1 profit $4,100 vs Run 2 profit $16,586). Report the higher-profit run; the (1+dim%)^q term makes the objective non-convex, so GRG Nonlinear is only guaranteed to find a local optimum.
A25: Check 4 — Check figures (constraint & feasibility reconciliation)
A26: Constraint | B26: Used | C26: Cap | D26: Status
A27: Tomatoes beds | B27: ='Solver Model'!B4 -> 10 | C27: =Inputs!B25 -> 20 | D27: =IF(B27<=C27,"OK","EXCEEDS") -> OK
A28: Carrots beds | B28: ='Solver Model'!B5 -> 19 | C28: =Inputs!B26 -> 20 | D28: =IF(B28<=C28,"OK","EXCEEDS") -> OK
A29: Mesclun beds | B29: ='Solver Model'!B6 -> 28 | C29: =Inputs!B27 -> 30 | D29: =IF(B29<=C29,"OK","EXCEEDS") -> OK
A30: Total beds | B30: ='Solver Model'!B7 -> 57 | C30: =Inputs!B5 -> 64 | D30: =IF(B30<=C30,"OK","EXCEEDS") -> OK
A31: Temp workers (raw required) | B31: ='P&L'!B13 -> 3 | C31: =Inputs!B21 -> 4 | D31: =IF(B31<=C31,"OK","EXCEEDS") -> OK
A32: Total labor hours | B32: =Engine!F9 -> 5029.3846 | C32: =Inputs!B14+Inputs!B21*Inputs!B19 -> 6480 | D32: =IF(B32<=C32,"OK","EXCEEDS") -> OK
A34: Check 5 — Formulas, not pasted values
A35: All revenue, fertilizer, labor-hour, labor-cost, and profit figures on the P&L, Engine, and Solver Model sheets are live formulas referencing the Inputs sheet and the three decision cells ('Solver Model'!B4:B6) — confirm by selecting any output cell and reading the formula bar. The only intentionally hardcoded numbers in the workbook are: (a) the literal 'by-hand' check in Audit!B5 (used only to verify the engine formula, per Check 1), and (b) the two Solver run starting points (0/0/0 and 20/0/0) entered as Solver's initial seed values in 'Solver Model'!B38:D39 before optimization.
A41: Spot list
A42: Cell | B42: Sheet | C42: Contains
A43: B22 (Profit_ConventionA) | B43: P&L | C43: Live formula
A44: B19 (Objective_Profit, linked) | B44: Solver Model | C44: Live formula (link)
A45: F9 (Total Labor Hours) | B45: Engine | C45: Live formula
A46: B13 (Workers required, raw) | B46: P&L | C46: Live formula
